2023-08-27 11:23:41.293 WARNING (Recorder) [homeassistant.components.recorder.util] The system could not validate that the sqlite3 database at //config/home-assistant_v2.db was shutdown cleanly
2023-08-27 11:23:41.351 WARNING (Recorder) [homeassistant.components.recorder.util] Ended unfinished session (id=2 from 2023-08-25 15:46:58.936235)
2023-08-27 11:23:42.689 ERROR (MainThread) [aiohttp.server] Error handling request
Traceback (most recent call last):
  File "/usr/local/lib/python3.11/site-packages/aiohttp/web_protocol.py", line 332, in data_received
    messages, upgraded, tail = self._request_parser.feed_data(data)
                               ^^^^^^^^^^^^^^^^^^^^^^^^^^^^^^^^^^^^
  File "aiohttp/_http_parser.pyx", line 557, in aiohttp._http_parser.HttpParser.feed_data
aiohttp.http_exceptions.BadStatusLine: 400, message:
  Bad status line "Invalid method encountered:\n\n  b'\\x16\\x03\\x01\\x02'\n    ^"
2023-08-27 11:23:42.730 ERROR (MainThread) [aiohttp.server] Error handling request
Traceback (most recent call last):
  File "/usr/local/lib/python3.11/site-packages/aiohttp/web_protocol.py", line 332, in data_received
    messages, upgraded, tail = self._request_parser.feed_data(data)
                               ^^^^^^^^^^^^^^^^^^^^^^^^^^^^^^^^^^^^
  File "aiohttp/_http_parser.pyx", line 557, in aiohttp._http_parser.HttpParser.feed_data
aiohttp.http_exceptions.BadStatusLine: 400, message:
  Bad status line "Invalid method encountered:\n\n  b'\\x16\\x03\\x01\\x02'\n    ^"
2023-08-27 11:23:56.907 ERROR (MainThread) [aiohttp.server] Error handling request
Traceback (most recent call last):
  File "/usr/local/lib/python3.11/site-packages/aiohttp/web_protocol.py", line 332, in data_received
    messages, upgraded, tail = self._request_parser.feed_data(data)
                               ^^^^^^^^^^^^^^^^^^^^^^^^^^^^^^^^^^^^
  File "aiohttp/_http_parser.pyx", line 557, in aiohttp._http_parser.HttpParser.feed_data
aiohttp.http_exceptions.BadStatusLine: 400, message:
  Bad status line "Invalid method encountered:\n\n  b'\\x16\\x03\\x01\\x02'\n    ^"
2023-08-27 11:23:56.915 ERROR (MainThread) [aiohttp.server] Error handling request
Traceback (most recent call last):
  File "/usr/local/lib/python3.11/site-packages/aiohttp/web_protocol.py", line 332, in data_received
    messages, upgraded, tail = self._request_parser.feed_data(data)
                               ^^^^^^^^^^^^^^^^^^^^^^^^^^^^^^^^^^^^
  File "aiohttp/_http_parser.pyx", line 557, in aiohttp._http_parser.HttpParser.feed_data
aiohttp.http_exceptions.BadStatusLine: 400, message:
  Bad status line "Invalid method encountered:\n\n  b'\\x16\\x03\\x01\\x02'\n    ^"
2023-08-27 11:24:14.359 ERROR (MainThread) [aiohttp.server] Error handling request
Traceback (most recent call last):
  File "/usr/local/lib/python3.11/site-packages/aiohttp/web_protocol.py", line 332, in data_received
    messages, upgraded, tail = self._request_parser.feed_data(data)
                               ^^^^^^^^^^^^^^^^^^^^^^^^^^^^^^^^^^^^
  File "aiohttp/_http_parser.pyx", line 557, in aiohttp._http_parser.HttpParser.feed_data
aiohttp.http_exceptions.BadStatusLine: 400, message:
  Bad status line "Invalid method encountered:\n\n  b'\\x16\\x03\\x01\\x02'\n    ^"
2023-08-27 11:24:14.367 ERROR (MainThread) [aiohttp.server] Error handling request
Traceback (most recent call last):
  File "/usr/local/lib/python3.11/site-packages/aiohttp/web_protocol.py", line 332, in data_received
    messages, upgraded, tail = self._request_parser.feed_data(data)
                               ^^^^^^^^^^^^^^^^^^^^^^^^^^^^^^^^^^^^
  File "aiohttp/_http_parser.pyx", line 557, in aiohttp._http_parser.HttpParser.feed_data
aiohttp.http_exceptions.BadStatusLine: 400, message:
  Bad status line "Invalid method encountered:\n\n  b'\\x16\\x03\\x01\\x02'\n    ^"
2023-08-27 11:24:15.440 ERROR (MainThread) [aiohttp.server] Error handling request
Traceback (most recent call last):
  File "/usr/local/lib/python3.11/site-packages/aiohttp/web_protocol.py", line 332, in data_received
    messages, upgraded, tail = self._request_parser.feed_data(data)
                               ^^^^^^^^^^^^^^^^^^^^^^^^^^^^^^^^^^^^
  File "aiohttp/_http_parser.pyx", line 557, in aiohttp._http_parser.HttpParser.feed_data
aiohttp.http_exceptions.BadStatusLine: 400, message:
  Bad status line "Invalid method encountered:\n\n  b'\\x16\\x03\\x01\\x02'\n    ^"
2023-08-27 11:24:15.446 ERROR (MainThread) [aiohttp.server] Error handling request
Traceback (most recent call last):
  File "/usr/local/lib/python3.11/site-packages/aiohttp/web_protocol.py", line 332, in data_received
    messages, upgraded, tail = self._request_parser.feed_data(data)
                               ^^^^^^^^^^^^^^^^^^^^^^^^^^^^^^^^^^^^
  File "aiohttp/_http_parser.pyx", line 557, in aiohttp._http_parser.HttpParser.feed_data
aiohttp.http_exceptions.BadStatusLine: 400, message:
  Bad status line "Invalid method encountered:\n\n  b'\\x16\\x03\\x01\\x02'\n    ^"
2023-08-27 11:24:20.467 ERROR (MainThread) [aiohttp.server] Error handling request
Traceback (most recent call last):
  File "/usr/local/lib/python3.11/site-packages/aiohttp/web_protocol.py", line 332, in data_received
    messages, upgraded, tail = self._request_parser.feed_data(data)
                               ^^^^^^^^^^^^^^^^^^^^^^^^^^^^^^^^^^^^
  File "aiohttp/_http_parser.pyx", line 557, in aiohttp._http_parser.HttpParser.feed_data
aiohttp.http_exceptions.BadStatusLine: 400, message:
  Bad status line "Invalid method encountered:\n\n  b'\\x16\\x03\\x01\\x02'\n    ^"
2023-08-27 11:24:20.474 ERROR (MainThread) [aiohttp.server] Error handling request
Traceback (most recent call last):
  File "/usr/local/lib/python3.11/site-packages/aiohttp/web_protocol.py", line 332, in data_received
    messages, upgraded, tail = self._request_parser.feed_data(data)
                               ^^^^^^^^^^^^^^^^^^^^^^^^^^^^^^^^^^^^
  File "aiohttp/_http_parser.pyx", line 557, in aiohttp._http_parser.HttpParser.feed_data
aiohttp.http_exceptions.BadStatusLine: 400, message:
  Bad status line "Invalid method encountered:\n\n  b'\\x16\\x03\\x01\\x02'\n    ^"
2023-08-27 11:24:50.503 ERROR (MainThread) [aiohttp.server] Error handling request
Traceback (most recent call last):
  File "/usr/local/lib/python3.11/site-packages/aiohttp/web_protocol.py", line 332, in data_received
    messages, upgraded, tail = self._request_parser.feed_data(data)
                               ^^^^^^^^^^^^^^^^^^^^^^^^^^^^^^^^^^^^
  File "aiohttp/_http_parser.pyx", line 557, in aiohttp._http_parser.HttpParser.feed_data
aiohttp.http_exceptions.BadStatusLine: 400, message:
  Bad status line "Invalid method encountered:\n\n  b'\\x16\\x03\\x01\\x02'\n    ^"
2023-08-27 11:24:50.511 ERROR (MainThread) [aiohttp.server] Error handling request
Traceback (most recent call last):
  File "/usr/local/lib/python3.11/site-packages/aiohttp/web_protocol.py", line 332, in data_received
    messages, upgraded, tail = self._request_parser.feed_data(data)
                               ^^^^^^^^^^^^^^^^^^^^^^^^^^^^^^^^^^^^
  File "aiohttp/_http_parser.pyx", line 557, in aiohttp._http_parser.HttpParser.feed_data
aiohttp.http_exceptions.BadStatusLine: 400, message:
  Bad status line "Invalid method encountered:\n\n  b'\\x16\\x03\\x01\\x02'\n    ^"
